<?xml version="1.0"?>
<robot name="my_robot">
    <!-- Gazebo plugins -->
    <gazebo>
        <static>true</static>
        <plugin filename="gz_ros2_control-system" name="gz_ros2_control::GazeboSimROS2ControlPlugin">
            <parameters>$(find simulation)/urdf/control.yaml</parameters>
            <ros>
                <remapping>/controller_manager/robot_description:=/robot_description</remapping>
            </ros>
        </plugin>
    </gazebo>

    <!-- Materials -->
    <material name="grey">
        <color rgba="0.7 0.7 0.7 1"/>
    </material>

    <material name="green">
        <color rgba="0 0.6 0 1"/>
    </material>

    <material name="white">
        <color rgba="1 1 1 1"/>
    </material>

    <!-- Links -->
    <link name="base_link">
        <visual>
            <origin xyz="0 0 1" rpy="1.57 0 0"/>
            <material name="white"/>
            <geometry>
                <box size=".05 .05 2"/>
            </geometry>
        </visual>
    </link>

    <link name="left_rod">
        <inertial>
            <mass value=".1"/>
            <inertia ixx=".1" ixy="0" ixz="0" iyy=".1" iyz="0" izz=".075"/>
        </inertial>
        <visual>
            <origin xyz="0 -1 .5" rpy="0 0 0"/>
            <material name="white"/>
            <geometry>
                <box size=".05 .05 1"/>
            </geometry>
        </visual>
    </link>

    <link name="right_rod">
        <inertial>
            <mass value=".1"/>
            <inertia ixx=".1" ixy="0" ixz="0" iyy=".1" iyz="0" izz=".075"/>
        </inertial>
        <visual>
            <origin xyz="0 1 .5" rpy="0 0 0"/>
            <material name="white"/>
            <geometry>
                <box size=".05 .05 1"/>
            </geometry>
        </visual>
    </link>

    <link name="central_piece">
        <inertial>
            <mass value=".1"/>
            <inertia ixx=".1" ixy="0" ixz="0" iyy=".1" iyz="0" izz=".075"/>
        </inertial>
        <visual>
            <origin xyz="0 0 1.06" rpy="1.57 0 0"/>
            <material name="grey"/>
            <geometry>
                <box size=".07 .07 .05"/>
            </geometry>
        </visual>
    </link>

    <link name="pendulum">
        <inertial>
            <mass value=".1"/>
            <inertia ixx=".1" ixy="0" ixz="0" iyy=".1" iyz="0" izz=".075"/>
        </inertial>
        <visual>
            <origin xyz="0 0 -.15" rpy="0 0 0"/>
            <material name="green"/>
            <geometry>
                <box size=".05 .05 0.3"/>
            </geometry>
        </visual>
    </link>

    <!-- Joints -->
    <joint name="central_piece_joint" type="prismatic">
        <parent link="base_link"/>
        <child link="central_piece"/>
        <origin xyz="0 0 0" rpy="0 0 0"/>
        <axis xyz="0 1 0"/>
        <limit effort="1000.0" lower="-.9" upper=".9" velocity="0.5"/>
    </joint>

    <joint name="pendulum_joint" type="continuous">
        <parent link="central_piece"/>
        <child link="pendulum"/>
        <origin xyz="0.06 0 1.06" rpy="0 0 0"/>
        <axis xyz="1 0 0"/>
    </joint>

    <joint name="right_rod_joint" type="fixed">
        <parent link="base_link"/>
        <child link="right_rod"/>
        <origin xyz="0 0 0" rpy="0 0 0"/>
    </joint>

    <joint name="left_rod_joint" type="fixed">
        <parent link="base_link"/>
        <child link="left_rod"/>
        <origin xyz="0 0 0" rpy="0 0 0"/>
    </joint>

    <!-- ROS 2 Control -->
    <ros2_control name="RobotSystem" type="system">
        <hardware>
            <plugin>gz_ros2_control/GazeboSimSystem</plugin>
        </hardware>
        <joint name="central_piece_joint">
            <command_interface name="velocity">
                <param name="min">-1000</param>
                <param name="max">1000</param>
            </command_interface>
            <state_interface name="position">
                <param name="initial_value">1.0</param>
            </state_interface>
            <state_interface name="velocity"/>
            <state_interface name="effort"/>
        </joint>

        <!-- No command interface for pendulum_joint since it moves freely -->
        <joint name="pendulum_joint">
            <state_interface name="position">
                <param name="initial_value">1.0</param>
            </state_interface>
            <state_interface name="velocity"/>
            <state_interface name="effort"/>
        </joint>
    </ros2_control>

    <!-- Transmissions -->
    <transmission name="central_piece_transmission">
        <type>transmission_interface/SimpleTransmission</type>
        <joint name="central_piece_joint">
            <hardwareInterface>VelocityJointInterface</hardwareInterface>
        </joint>
        <actuator name="central_piece_motor">
            <hardwareInterface>VelocityJointInterface</hardwareInterface>
            <mechanicalReduction>1</mechanicalReduction>
        </actuator>
    </transmission>
</robot>
