<?xml version = "1.0"?>
<sdf version='1.10'>
<world name="default">
  <model name='my_robot'>
    <!-- Gazebo plugins -->
      <plugin name="gazebo_ros_control" filename="libgazebo_ros_control.so">
        <robotNamespace>/</robotNamespace>
        <robotSimType>gazebo_ros_control/GazeboRosControlPlugin</robotSimType>
      </plugin>

      <plugin name="joint_state_publisher" filename="libgazebo_ros_joint_state_publisher.so">
        <robotNamespace>/</robotNamespace>
        <publishFrequency>50.0</publishFrequency>
      </plugin>
      
    <link name='base_link'>
      <inertial>
        <pose>0 0 0 0 0 0</pose>
        <mass>0.29999999999999999</mass>
        <inertia>
          <ixx>0.29999999999999999</ixx>
          <ixy>0</ixy>
          <ixz>0</ixz>
          <iyy>0.29999999999999999</iyy>
          <iyz>0</iyz>
          <izz>0.22500000000000001</izz>
        </inertia>
      </inertial>
      <visual name='base_link_visual'>
        <pose>0 0 1 1.5700000000000001 0 0</pose>
        <geometry>
          <box>
            <size>0.050000000000000003 0.050000000000000003 2</size>
          </box>
        </geometry>
        <material>
          <diffuse>1 1 1 1</diffuse>
          <ambient>1 1 1 1</ambient>
        </material>
      </visual>
      <visual name='base_link_fixed_joint_lump__left_rod_visual_1'>
        <pose>0 -1 0.5 0 0 0</pose>
        <geometry>
          <box>
            <size>0.050000000000000003 0.050000000000000003 1</size>
          </box>
        </geometry>
        <material>
          <diffuse>1 1 1 1</diffuse>
          <ambient>1 1 1 1</ambient>
        </material>
      </visual>
      <visual name='base_link_fixed_joint_lump__right_rod_visual_2'>
        <pose>0 1 0.5 0 0 0</pose>
        <geometry>
          <box>
            <size>0.050000000000000003 0.050000000000000003 1</size>
          </box>
        </geometry>
        <material>
          <diffuse>1 1 1 1</diffuse>
          <ambient>1 1 1 1</ambient>
        </material>
      </visual>
    </link>
    <joint name='central_piece_joint' type='prismatic'>
      <pose relative_to='base_link'>0 0 0 0 0 0</pose>
      <parent>base_link</parent>
      <child>central_piece</child>
      <axis>
        <xyz>0 1 0</xyz>
        <limit>
          <lower>-0.90000000000000002</lower>
          <upper>0.90000000000000002</upper>
          <effort>1000</effort>
          <velocity>0.5</velocity>
        </limit>
        <dynamics>
          <spring_reference>0</spring_reference>
          <spring_stiffness>0</spring_stiffness>
        </dynamics>
      </axis>
    </joint>
    <link name='central_piece'>
      <pose relative_to='central_piece_joint'>0 0 0 0 0 0</pose>
      <inertial>
        <pose>0 0 0 0 0 0</pose>
        <mass>0.10000000000000001</mass>
        <inertia>
          <ixx>0.10000000000000001</ixx>
          <ixy>0</ixy>
          <ixz>0</ixz>
          <iyy>0.10000000000000001</iyy>
          <iyz>0</iyz>
          <izz>0.074999999999999997</izz>
        </inertia>
      </inertial>
      <visual name='central_piece_visual'>
        <pose>0 0 1.0600000000000001 1.5700000000000001 0 0</pose>
        <geometry>
          <box>
            <size>0.070000000000000007 0.070000000000000007 0.050000000000000003</size>
          </box>
        </geometry>
        <material>
          <diffuse>0.875 0.875 0.875 1</diffuse>
          <ambient>0.875 0.875 0.875 1</ambient>
        </material>
      </visual>
    </link>
    <joint name='pendulum_joint' type='revolute'>
      <pose relative_to='central_piece'>0.059999999999999998 0 1.0600000000000001 0 0 0</pose>
      <parent>central_piece</parent>
      <child>pendulum</child>
      <axis>
        <xyz>1 0 0</xyz>
        <limit>
          <lower>-inf</lower>
          <upper>inf</upper>
        </limit>
        <dynamics>
          <spring_reference>0</spring_reference>
          <spring_stiffness>0</spring_stiffness>
        </dynamics>
      </axis>
    </joint>
    <link name='pendulum'>
      <pose relative_to='pendulum_joint'>0 0 0 0 0 0</pose>
      <inertial>
        <pose>0 0 0 0 0 0</pose>
        <mass>0.10000000000000001</mass>
        <inertia>
          <ixx>0.10000000000000001</ixx>
          <ixy>0</ixy>
          <ixz>0</ixz>
          <iyy>0.10000000000000001</iyy>
          <iyz>0</iyz>
          <izz>0.074999999999999997</izz>
        </inertia>
      </inertial>
      <visual name='pendulum_visual'>
        <pose>0 0 -0.14999999999999999 0 0 0</pose>
        <geometry>
          <box>
            <size>0.050000000000000003 0.050000000000000003 0.29999999999999999</size>
          </box>
        </geometry>
        <material>
          <diffuse>0 0.75000006 0 1</diffuse>
          <ambient>0 0.75000006 0 1</ambient>
        </material>
      </visual>
    </link>
    <frame name='left_rod_joint' attached_to='base_link'>
      <pose>0 0 0 0 0 0</pose>
    </frame>
    <frame name='left_rod' attached_to='left_rod_joint'>
      <pose>0 0 0 0 0 0</pose>
    </frame>
    <frame name='right_rod_joint' attached_to='base_link'>
      <pose>0 0 0 0 0 0</pose>
    </frame>
    <frame name='right_rod' attached_to='right_rod_joint'>
      <pose>0 0 0 0 0 0</pose>
    </frame>
    <joint name="fixed_joint" type="fixed">
        <parent>world</parent>
        <child>base_link</child>
        <pose>0 0 0 0 0 0</pose>
      </joint>
    <physics type='ode'>
      <max_step_size>0.001</max_step_size>
      <real_time_factor>1</real_time_factor>
      <real_time_update_rate>1000</real_time_update_rate>
      <solver>
        <type>quick</type>
        <iters>50</iters>
        <sor>1.3</sor>
      </solver>
      <constraints>
        <cfm>0.0</cfm>
        <erp>0.2</erp>
      </constraints>
    </physics>
  </model>
</world>
</sdf>